Workbook

Sheet README
A1: 식별자 범위 | C1: 미션 종류 | E1: 보상 종류 | G1: 튜토리얼 종류 | I1: 리소스 종류 | K1: 타겟 종류 | M1: 아이템 종류 | O1: 스킬 종류 | Q1: 객체 종류 | S1: 효과 종류 | U1: 어빌리티 종류
A2: 대분류 (T) [0 ~ 20] | B2: 100000000 | C2: 없음 | D2: -1 | E2: 없음 | F2: -1 | G2: 없음 | H2: -1 | I2: 없음 | J2: -1 | K2: 없음 | L2: -1 | M2: 없음 | N2: -1 | O2: 없음 | P2: -1 | Q2: 없음 | R2: -1 | S2: 없음 | T2: -1 | U2: 없음 | V2: -1
A3: 중분류 - 1 (ST) [0 ~ 8] | B3: 10000000 | K3: 아이템 | L3: 0 | M3: 일반 코인 | N3: 0 | O3: 플레이어 공격 1 - 1 | P3: 0 | U3: 레벨 | V3: 0
A4: 중분류 - 2 (KT) [0 ~ 98 or 998] | B4: 100000 | K4: 아이템 레벨 | L4: 100 | M4: 코인 상자 코인 | N4: 100000 | O4: 일반 적 공격 1 - 1 | P4: 10000000 | U4: 레벨 증가 | V4: 10000000
A5: 소분류 (SKT) [0 ~ 998] | B5: 100 | K5: 아이템 경험치 | L5: 200 | O5: 보스 적 공격 1 - 1 | P5: 20000000 | U5: 레벨 감소 | V5: 20000000
A6: 베리에이션 (DSKT) [0 ~ 98] | B6: 1 | K6: 아이템 개수 | L6: 300 | M6: 힌트 | N6: 100100000
K7: 아이템 강화 | L7: 400 | M7: 이어하기 | N7: 100100100 | U7: 경험치 | V7: 100
A8: 값 타입 | M8: 재배치 | N8: 100100200 | U8: 경험치 증가 | V8: 10000100
A9: 없음 | B9: -1 | K9: 스킬 | L9: 100000000 | U9: 경험치 감소 | V9: 20000100
A10: 정수 | B10: 0 | K10: 스킬 레벨 | L10: 100000100 | M10: 광고 제거 | N10: 200000000
A11: 실수 | B11: 1 | K11: 스킬 경험치 | L11: 100000200 | U11: 개수 | V11: 200
K12: 스킬 개수 | L12: 100000300 | U12: 개수 증가 | V12: 10000200
A13: 결제 타입 | K13: 스킬 강화 | L13: 100000400 | U13: 개수 감소 | V13: 20000200
A14: 없음 | B14: -1
A15: 광고 | B15: 0 | K15: 객체 | L15: 200000000 | U15: 강화 | V15: 300
A16: 인앱결제 | B16: 1 | K16: 객체 레벨 | L16: 200000100 | U16: 강화 증가 | V16: 10000300
A17: 타겟 | B17: 2 | K17: 객체 경험치 | L17: 200000200 | U17: 강화 감소 | V17: 20000300
K18: 객체 개수 | L18: 200000300
A19: 타겟 타입 | K19: 객체 강화 | L19: 200000400 | U19: 체력 - 1 | V19: 100000
A20: 없음 | B20: -1 | U20: 체력 - 2 | V20: 100001
A21: 아이템 | B21: 0 | K21: 어빌리티 | L21: 300000000 | U21: 체력 증가 - 1 | V21: 10100000
A22: 스킬 | B22: 1 | K22: 어빌리티 레벨 | L22: 300000100 | U22: 체력 감소 - 1 | V22: 20100000
A23: 객체 | B23: 2
A24: 어빌리티 | B24: 3 | U24: 마력 - 1 | V24: 100100
U25: 마력 - 2 | V25: 100101
A26: 종류 그룹 타입 | U26: 마력 증가 - 1 | V26: 10100100
A27: 없음 | B27: -1 | U27: 마력 감소 - 1 | V27: 20100100
A28: 중분류 - 1 | B28: 0
A29: 중분류 - 2 | B29: 1 | U29: 기력 - 1 | V29: 100200
A30: 소분류 | B30: 2 | U30: 기력 - 2 | V30: 100201
U31: 기력 증가 - 1 | V31: 10100200
A32: 에피소드 식별자 범위 | U32: 기력 감소 - 1 | V32: 20100200
A33: 레벨 | B33: 0 ~ 9998
A34: 스테이지 | B34: 0 ~ 998 | U34: 회복 - 1 | V34: 200000
A35: 챕터 | B35: 0 ~ 98 | U35: 회복 - 2 | V35: 200001
U36: 회복 증가 - 1 | V36: 10200000
A37: 에피소드 종류 | U37: 회복 감소 - 1 | V37: 20200000
A38: 없음 | B38: -1
A39: 일반 레벨 | B39: 0 | U39: 체력 회복 - 1 | V39: 200100
A40: 보스 레벨 | B40: 100000 | U40: 체력 회복 - 2 | V40: 200101
...

Sheet Val
A1: Description | B1: Replace | C1: ID | D1: Val | E1: ValType
A2: 광고 지연 | B2: 0 | C2: DELAY_ADS | D2: 60 | E2: =README!$B$11 -> 1
A3: 광고 시간 간격 | B3: 0 | C3: DELTA_T_ADS | D3: 10 | E3: =README!$B$11 -> 1
A4: 기본 퀄리티 수준 | B4: 0 | C4: DEF_QUALITY_LEVEL | D4: 2 | E4: =README!$B$10 -> 0
A5: 모바일 퀄리티 수준 | B5: 0 | C5: MOBILE_QUALITY_LEVEL | D5: 2 | E5: =README!$B$10 -> 0
A6: 데스크 탑 퀄리티 수준 | B6: 0 | C6: DESKTOP_QUALITY_LEVEL | D6: 3 | E6: =README!$B$10 -> 0
A7: 콘솔 퀄리티 수준 | B7: 0 | C7: CONSOLE_QUALITY_LEVEL | D7: 5 | E7: 0
A8: 휴대용 콘솔 퀄리티 수준 | B8: 0 | C8: HANDHELD_CONSOLE_QUALITY_LEVEL | D8: 2 | E8: 0
A9: 기본 타겟 프레임 | B9: 0 | C9: DEF_TARGET_FRAME_RATE | D9: 60 | E9: =README!$B$10 -> 0
A10: 모바일 타겟 프레임 | B10: 0 | C10: MOBILE_TARGET_FRAME_RATE | D10: 60 | E10: =README!$B$10 -> 0
A11: 데스크 탑 타겟 프레임 | B11: 0 | C11: DESKTOP_TARGET_FRAME_RATE | D11: 60 | E11: =README!$B$10 -> 0
A12: 콘솔 타겟 프레임 | B12: 0 | C12: CONSOLE_TARGET_FRAME_RATE | D12: 60 | E12: 0
A13: 휴대용 콘솔 타겟 프레임 | B13: 0 | C13: HANDHELD_CONSOLE_TARGET_FRAME_RATE | D13: 60 | E13: 0

Sheet Str
A1: Description | B1: Replace | C1: ID | D1: Korean | E1: English
A2: 시작 씬 로딩 텍스트 | B2: 0 | C2: START_SM_LOADING_TEXT | D2: Loading... | E2: Loading...
A3: 종료 팝업 메세지 | B3: 0 | C3: QUIT_P_MSG | D3: 게임을 종료하시겠습니까? | E3: Do you want to quit the game?
A4: 그만두기 팝업 메세지 | B4: 0 | C4: LEAVE_P_MSG | D4: 게임을 그만두시겠습니까? | E4: Do you want to leave the game?
A5: 업데이트 팝업 메세지 | B5: 0 | C5: UPDATE_P_MSG | D5: 새로운 버전이 출시되었습니다.\n업데이트 하시겠습니까? | E5: A new version has been released.\nWould you like to update it?
A6: 로드 팝업 메세지 | B6: 0 | C6: LOAD_P_MSG | D6: 진행 상황을 로드하시겠습니까?\n<color=#ff0000ff><size=24>(로드 시 현재 진행 상황은 복구 할 수 없습니다)</size></color> | E6: Do you want to load progress?\n<color=#ff0000ff><size=24>(When loading, current progress cannot be recovered)</size></color>
A7: 저장 팝업 메세지 | B7: 0 | C7: SAVE_P_MSG | D7: 진행 상황을 저장하시겠습니까?\n<color=#ff0000ff><size=24>(저장 시 이전 진행 상황은 복구 할 수 없습니다)</size></color> | E7: Do you want to save progress?\n<color=#ff0000ff><size=24>(When saving, previous progress cannot be recovered)</size></color>
A8: 추적 설명 팝업 타이틀 | B8: 0 | C8: TRACKING_DP_TITLE | D8: 알림 | E8: Notice
A9: 추적 설명 팝업 메세지 | B9: 0 | C9: TRACKING_DP_MSG | D9: 다음 화면에서\n추적 허용 | E9: Allow tracking on the\nnext screen for
A10: 추적 설명 팝업 설명 메세지 1 | B10: 0 | C10: TRACKING_DP_DESC_MSG_01 | D10: - 특별한 프로모션을 제공해\n드립니다 | E10: - Special offers and promotions\njust for you
A11: 추적 설명 팝업 설명 메세지 2 | B11: 0 | C11: TRACKING_DP_DESC_MSG_02 | D11: - 관심사에 맞는 광고를 보여\n드립니다 | E11: - Advertisements that match\nyour interests
A12: 추적 설명 팝업 설명 메세지 3 | B12: 0 | C12: TRACKING_DP_DESC_MSG_03 | D12: - 개인화 된 경험을 향상 시켜\n드립니다 | E12: - An improved personalized\nexperience over time
A13: 공용 로그인 성공 메세지 | B13: 0 | C13: C_ON_LOGIN_MSG | D13: 로그인했습니다 | E13: You have successfully login
... A85: 에디터 챕터 제거 팝업 메세지 | B85: 0 | C85: EDITOR_REMOVE_CP_MSG | D85: 챕터를 제거하시겠습니까? | E85: Do you want to remove the chapter?

Sheet Calc
A1: NOEX_Description | B1: NOEX_T | C1: NOEX_ST | D1: NOEX_KT | E1: NOEX_SKT | F1: NOEX_DSKT | G1: Replace | H1: Flags_01 | I1: Flags_02 | J1: Flags_03 | K1: Name | L1: Desc | M1: CalcKinds | N1: PrevCalcKinds | O1: NextCalcKinds | P1: Calc
A2: 어빌리티 수식 샘플 | B2: 0 | C2: 0 | D2: 0 | E2: 0 | F2: 0 | G2: 0 | H2: 0 | I2: 0 | J2: 0 | M2: =IF($A2="", -1, ($B2*README!$B$2)+($C2*README!$B$3)+($D2*README!$B$4)+($E2*README!$B$5)+($F2*README!$B$6)) -> 0 | N2: =IF($A2="", -1, ($B2*README!$B$2)+($C2*README!$B$3)+($D2*README!$B$4)+($E2*README!$B$5)+($F2*README!$B$6)-1) -> -1 | O2: =IF($A2="", -1, ($B2*README!$B$2)+($C2*README!$B$3)+($D2*README!$B$4)+($E2*README!$B$5)+($F2*README!$B$6)+1) -> 1

Sheet Tutorial
A1: NOEX_Description | B1: NOEX_T | C1: NOEX_ST | D1: NOEX_KT | E1: NOEX_SKT | F1: NOEX_DSKT | G1: Replace | H1: Flags_01 | I1: Flags_02 | J1: Flags_03 | K1: Name | L1: Desc | M1: TutorialKinds | N1: PrevTutorialKinds | O1: NextTutorialKinds | P1: RewardKinds_01 | Q1: Str_01
A2: 플레이 튜토리얼 샘플 | B2: 0 | C2: 0 | D2: 0 | E2: 0 | F2: 0 | G2: 0 | H2: 0 | I2: 0 | J2: 0 | M2: =IF($A2="", -1, ($B2*README!$B$2)+($C2*README!$B$3)+($D2*README!$B$4)+($E2*README!$B$5)+($F2*README!$B$6)) -> 0 | N2: =IF($A2="", -1, ($B2*README!$B$2)+($C2*README!$B$3)+($D2*README!$B$4)+($E2*README!$B$5)+($F2*README!$B$6)-1) -> -1 | O2: =IF($A2="", -1, ($B2*README!$B$2)+($C2*README!$B$3)+($D2*README!$B$4)+($E2*README!$B$5)+($F2*README!$B$6)+1) -> 1 | P2: =README!$F$2 -> -1
A3: 도움말 튜토리얼 샘플 | B3: 1 | C3: 0 | D3: 0 | E3: 0 | F3: 0 | G3: 0 | H3: 0 | I3: 0 | J3: 0 | M3: =IF($A3="", -1, ($B3*README!$B$2)+($C3*README!$B$3)+($D3*README!$B$4)+($E3*README!$B$5)+($F3*README!$B$6)) -> 100000000 | N3: =IF($A3="", -1, ($B3*README!$B$2)+($C3*README!$B$3)+($D3*README!$B$4)+($E3*README!$B$5)+($F3*README!$B$6)-1) -> 99999999 | O3: =IF($A3="", -1, ($B3*README!$B$2)+($C3*README!$B$3)+($D3*README!$B$4)+($E3*README!$B$5)+($F3*README!$B$6)+1) -> 100000001 | P3: =README!$F$2 -> -1

Sheet FX
A1: NOEX_Description | B1: NOEX_T | C1: NOEX_ST | D1: NOEX_KT | E1: NOEX_SKT | F1: NOEX_DSKT | G1: Replace | H1: Flags_01 | I1: Flags_02 | J1: Flags_03 | K1: Name | L1: Desc | M1: FXKinds | N1: PrevFXKinds | O1: NextFXKinds | P1: TimeInfo | Q1: ResKinds_01
A2: 타격 효과 샘플 | B2: 0 | C2: 0 | D2: 0 | E2: 0 | F2: 0 | G2: 0 | H2: 0 | I2: 0 | J2: 0 | M2: =IF($A2="", -1, ($B2*README!$B$2)+($C2*README!$B$3)+($D2*README!$B$4)+($E2*README!$B$5)+($F2*README!$B$6)) -> 0 | N2: =IF($A2="", -1, ($B2*README!$B$2)+($C2*README!$B$3)+($D2*README!$B$4)+($E2*README!$B$5)+($F2*README!$B$6)-1) -> -1 | O2: =IF($A2="", -1, ($B2*README!$B$2)+($C2*README!$B$3)+($D2*README!$B$4)+($E2*README!$B$5)+($F2*README!$B$6)+1) -> 1 | P2: =JOIN(", ", 0, 0, 0) -> 0, 0, 0 | Q2: =README!$J$2 -> -1
A3: 버프 효과 샘플 | B3: 1 | C3: 0 | D3: 0 | E3: 0 | F3: 0 | G3: 0 | H3: 0 | I3: 0 | J3: 0 | M3: =IF($A3="", -1, ($B3*README!$B$2)+($C3*README!$B$3)+($D3*README!$B$4)+($E3*README!$B$5)+($F3*README!$B$6)) -> 100000000 | N3: =IF($A3="", -1, ($B3*README!$B$2)+($C3*README!$B$3)+($D3*README!$B$4)+($E3*README!$B$5)+($F3*README!$B$6)-1) -> 99999999 | O3: =IF($A3="", -1, ($B3*README!$B$2)+($C3*README!$B$3)+($D3*README!$B$4)+($E3*README!$B$5)+($F3*README!$B$6)+1) -> 100000001 | P3: =JOIN(", ", 0, 0, 0) -> 0, 0, 0 | Q3: =README!$J$2 -> -1
A4: 디버프 효과 샘플 | B4: 2 | C4: 0 | D4: 0 | E4: 0 | F4: 0 | G4: 0 | H4: 0 | I4: 0 | J4: 0 | M4: =IF($A4="", -1, ($B4*README!$B$2)+($C4*README!$B$3)+($D4*README!$B$4)+($E4*README!$B$5)+($F4*README!$B$6)) -> 200000000 | N4: =IF($A4="", -1, ($B4*README!$B$2)+($C4*README!$B$3)+($D4*README!$B$4)+($E4*README!$B$5)+($F4*README!$B$6)-1) -> 199999999 | O4: =IF($A4="", -1, ($B4*README!$B$2)+($C4*README!$B$3)+($D4*README!$B$4)+($E4*README!$B$5)+($F4*README!$B$6)+1) -> 200000001 | P4: =JOIN(", ", 0, 0, 0) -> 0, 0, 0 | Q4: =README!$J$2 -> -1

Sheet LevelEpisode
A1: NOEX_Description | B1: NOEX_T | C1: NOEX_ST | D1: NOEX_KT | E1: NOEX_SKT | F1: NOEX_DSKT | G1: Replace | H1: Flags_01 | I1: Flags_02 | J1: Flags_03 | K1: Name | L1: Desc | M1: ID_01 | N1: ID_02 | O1: ID_03 | P1: PrevID_01 | Q1: PrevID_02 | R1: PrevID_03 | S1: NextID_01 | T1: NextID_02 | U1: NextID_03 | V1: Difficulty | W1: EpisodeKinds | X1: TutorialKinds | Y1: NumSubEpisodes | Z1: MaxNumEnemyObjs | AA1: Size | AB1: RewardKinds_01 | AC1: RecordValInfo_01 | AD1: ClearTargetInfo_01 | AE1: UnlockTargetInfo_01 | AF1: DropItemTargetInfo_01 | AG1: EnemyObjTargetInfo_01
A2: 레벨 1 | B2: 0 | C2: 0 | D2: 0 | E2: 0 | F2: 0 | G2: 0 | H2: 0 | I2: 0 | J2: 0 | M2: =IF($A2="", -1, $F2) -> 0 | N2: =IF($A2="", -1, $E2) -> 0 | O2: =IF($A2="", -1, $D2) -> 0 | P2: =IF($A2="", -1, $M2-1) -> -1 | Q2: =IF($A2="", -1, $N2-1) -> -1 | R2: =IF($A2="", -1, $O2-1) -> -1 | S2: =IF($A2="", -1, $M2+1) -> 1 | T2: =IF($A2="", -1, $N2+1) -> 1 | U2: =IF($A2="", -1, $O2+1) -> 1 | V2: =README!$B$49 -> -1 | W2: =README!$B$38 -> -1 | X2: =README!$H$2 -> -1 | Y2: 0 | Z2: 0 | AA2: =JOIN(", ", 1, 1, 1) -> 1, 1, 1 | AB2: =README!$F$2 -> -1 | AC2: =JOIN(", ", README!$B$14, 0) -> -1, 0 | AD2: =JOIN(", ", README!$L$2, README!$B$27, -1, README!$B$9, 0) -> -1, -1, -1, -1, 0 | AE2: =JOIN(", ", README!$L$2, README!$B$27, -1, README!$B$9, 0) -> -1, -1, -1, -1, 0 | AF2: =JOIN(", ", README!$L$3, README!$B$27, -1, README!$B$10, 0) -> 0, -1, -1, 0, 0 | AG2: =JOIN(", ", README!$L$15, README!$B$27, -1, README!$B$10, 0) -> 200000000, -1, -1, 0, 0

Sheet StageEpisode
A1: NOEX_Description | B1: NOEX_T | C1: NOEX_ST | D1: NOEX_KT | E1: NOEX_SKT | F1: NOEX_DSKT | G1: Replace | H1: Flags_01 | I1: Flags_02 | J1: Flags_03 | K1: Name | L1: Desc | M1: ID_01 | N1: ID_02 | O1: ID_03 | P1: PrevID_01 | Q1: PrevID_02 | R1: PrevID_03 | S1: NextID_01 | T1: NextID_02 | U1: NextID_03 | V1: Difficulty | W1: EpisodeKinds | X1: TutorialKinds | Y1: NumSubEpisodes | Z1: MaxNumEnemyObjs | AA1: Size | AB1: RewardKinds_01 | AC1: RecordValInfo_01 | AD1: ClearTargetInfo_01 | AE1: UnlockTargetInfo_01 | AF1: DropItemTargetInfo_01 | AG1: EnemyObjTargetInfo_01
A2: 스테이지 1 | B2: 0 | C2: 0 | D2: 0 | E2: 0 | F2: 0 | G2: 0 | H2: 0 | I2: 0 | J2: 0 | M2: 0 | N2: =IF($A2="", -1, $E2) -> 0 | O2: =IF($A2="", -1, $D2) -> 0 | P2: =IF($A2="", -1, $M2-1) -> -1 | Q2: =IF($A2="", -1, $N2-1) -> -1 | R2: =IF($A2="", -1, $O2-1) -> -1 | S2: =IF($A2="", -1, $M2+1) -> 1 | T2: =IF($A2="", -1, $N2+1) -> 1 | U2: =IF($A2="", -1, $O2+1) -> 1 | V2: =README!$B$49 -> -1 | W2: =README!$B$38 -> -1 | X2: =README!$H$2 -> -1 | Y2: =COUNTIFS(LevelEpisode!$N:$N, $N2, LevelEpisode!$O:$O, $O2) -> 1 | Z2: 0 | AA2: =JOIN(", ", 1, 1, 1) -> 1, 1, 1 | AB2: =README!$F$2 -> -1 | AC2: =JOIN(", ", README!$B$14, 0) -> -1, 0 | AD2: =JOIN(", ", README!$L$2, README!$B$27, -1, README!$B$9, 0) -> -1, -1, -1, -1, 0 | AE2: =JOIN(", ", README!$L$2, README!$B$27, -1, README!$B$9, 0) -> -1, -1, -1, -1, 0 | AF2: =JOIN(", ", README!$L$3, README!$B$27, -1, README!$B$10, 0) -> 0, -1, -1, 0, 0 | AG2: =JOIN(", ", README!$L$15, README!$B$27, -1, README!$B$10, 0) -> 200000000, -1, -1, 0, 0

Sheet ChapterEpisode
A1: NOEX_Description | B1: NOEX_T | C1: NOEX_ST | D1: NOEX_KT | E1: NOEX_SKT | F1: NOEX_DSKT | G1: Replace | H1: Flags_01 | I1: Flags_02 | J1: Flags_03 | K1: Name | L1: Desc | M1: ID_01 | N1: ID_02 | O1: ID_03 | P1: PrevID_01 | Q1: PrevID_02 | R1: PrevID_03 | S1: NextID_01 | T1: NextID_02 | U1: NextID_03 | V1: Difficulty | W1: EpisodeKinds | X1: TutorialKinds | Y1: NumSubEpisodes | Z1: MaxNumEnemyObjs | AA1: Size | AB1: RewardKinds_01 | AC1: RecordValInfo_01 | AD1: ClearTargetInfo_01 | AE1: UnlockTargetInfo_01 | AF1: DropItemTargetInfo_01 | AG1: EnemyObjTargetInfo_01
A2: 챕터 1 | B2: 0 | C2: 0 | D2: 0 | E2: 0 | F2: 0 | G2: 0 | H2: 0 | I2: 0 | J2: 0 | M2: =IF($A2="", -1, $F2) -> 0 | N2: =IF($A2="", -1, $E2) -> 0 | O2: =IF($A2="", -1, $D2) -> 0 | P2: =IF($A2="", -1, $M2-1) -> -1 | Q2: =IF($A2="", -1, $N2-1) -> -1 | R2: =IF($A2="", -1, $O2-1) -> -1 | S2: =IF($A2="", -1, $M2+1) -> 1 | T2: =IF($A2="", -1, $N2+1) -> 1 | U2: =IF($A2="", -1, $O2+1) -> 1 | V2: =README!$B$49 -> -1 | W2: =README!$B$38 -> -1 | X2: =README!$H$2 -> -1 | Y2: =COUNTIFS(StageEpisode!$O:$O, $O2) -> 1 | Z2: 0 | AA2: =JOIN(", ", 1, 1, 1) -> 1, 1, 1 | AB2: =README!$F$2 -> -1 | AC2: =JOIN(", ", README!$B$14, 0) -> -1, 0 | AD2: =JOIN(", ", README!$L$2, README!$B$27, -1, README!$B$9, 0) -> -1, -1, -1, -1, 0 | AE2: =JOIN(", ", README!$L$2, README!$B$27, -1, README!$B$9, 0) -> -1, -1, -1, -1, 0 | AF2: =JOIN(", ", README!$L$3, README!$B$27, -1, README!$B$10, 0) -> 0, -1, -1, 0, 0 | AG2: =JOIN(", ", README!$L$15, README!$B$27, -1, README!$B$10, 0) -> 200000000, -1, -1, 0, 0
